Workbook

Sheet P317202504-SBV-ABR25 compensado
A1: CFE - DIVISION CENTRO ORIENTE
A2: Parámetros de Facturación de Servicios Contratados por Permisionarios y sus Centros de Consumo
A3: Proceso del Permisionario: SBV-CE G Sanborns 2, S.A. de C.V.(Planta Sanborns)
A4: Abril del 2025 Período: 1 | Carga Local : 585 | CapacidadFuente : 1154
C5: KWH | H5: KW | L5: KVARH | M5: %FP | N5: KW Base | Q5: KW Inter | T5: KW Punta | W5: KW SemiPunta | Z5: Horas del período | AD5: Factor de carga
C6: Base | D6: Intermedia | E6: Punta | F6: SemiPunta | G6: TOTALES | H6: Base | I6: Intermedia | J6: Punta | K6: SemiPunta | N6: Fecha | O6: Hora | P6: Minutos | Q6: Fecha | R6: Hora | S6: Minutos | T6: Fecha | U6: Hora | V6: Minutos | W6: Fecha | X6: Hora | Y6: Minutos | Z6: Base | AA6: Intermedia | AB6: Punta | AC6: SemiPunta | AD6: Base | AE6: Intermedia | AF6: Punta | AG6: SemiPunta
A7: Resultados del Permisionario | B7: TOTAL PORTEADO O TRANSMISION | C7: 9673 | D7: 15298 | E7: 3891 | F7: 0 | G7: 28862 | H7: 0 | I7: 708 | J7: 0 | K7: 0 | L7: 0 | M7: 1 | N7: 45661 | O7: 0 | P7: 5 | Q7: 45661 | R7: 12 | S7: 50 | T7: 45661 | U7: 18 | V7: 5 | W7: 1 | X7: 0 | Y7: 0 | Z7: 32 | AA7: 70 | AB7: 18 | AC7: 0 | AD7: 0 | AE7: 100 | AF7: 0 | AG7: 0
B8: RESPALDO | C8: 1024 | D8: 10656 | E8: 3891 | F8: 0 | G8: 15572 | H8: 53 | I8: 286 | J8: 271 | K8: 0 | L8: 0 | M8: 1 | N8: 45781 | O8: 4 | P8: 55 | Q8: 45661 | R8: 13 | S8: 20 | T8: 45692 | U8: 18 | V8: 15 | W8: 1 | X8: 0 | Y8: 0 | Z8: 32 | AA8: 70 | AB8: 18 | AC8: 0 | AD8: 100 | AE8: 100 | AF8: 100 | AG8: 0
B9: FP DEL RESPALDO (Suministro Normal de la Planta) | C9: 1024 | D9: 10656 | E9: 3891 | F9: 0 | G9: 15572 | H9: 53 | I9: 286 | J9: 271 | K9: 0 | L9: 5001 | M9: 0.9521 | N9: 45781 | O9: 4 | P9: 55 | Q9: 45661 | R9: 13 | S9: 20 | T9: 45692 | U9: 18 | V9: 15 | W9: 1 | X9: 0 | Y9: 0 | Z9: 32 | AA9: 70 | AB9: 18 | AC9: 0 | AD9: 79.53 | AE9: 95.78 | AF9: 96.7 | AG9: 0
B10: BANDA A FAVOR DEL PERMISIONARIO | C10: 0 | D10: 0 | E10: 0 | F10: 0 | G10: 0 | H10: 0 | I10: 0 | J10: 0 | K10: 0 | L10: 0 | N10: 45661 | O10: 0 | P10: 5 | Q10: 45661 | R10: 6 | S10: 5 | T10: 45661 | U10: 18 | V10: 5 | W10: 1 | X10: 0 | Y10: 0 | Z10: 32 | AA10: 70 | AB10: 18 | AC10: 0 | AD10: 0 | AE10: 0 | AF10: 0 | AG10: 0
B11: BANDA A FAVOR DEL SUMINISTRADOR | C11: 0 | D11: 0 | E11: 0 | F11: 0 | G11: 0 | H11: 0 | I11: 0 | J11: 0 | K11: 0 | L11: 0 | N11: 45661 | O11: 0 | P11: 5 | Q11: 45661 | R11: 6 | S11: 5 | T11: 45661 | U11: 18 | V11: 5 | W11: 1 | X11: 0 | Y11: 0 | Z11: 32 | AA11: 70 | AB11: 18 | AC11: 0 | AD11: 0 | AE11: 0 | AF11: 0 | AG11: 0
B12: EXCEDENTES | C12: 0 | D12: 0 | E12: 0 | F12: 0 | G12: 0 | H12: 0 | I12: 0 | J12: 0 | K12: 0 | L12: 0 | N12: 45661 | O12: 0 | P12: 5 | Q12: 45661 | R12: 6 | S12: 5 | T12: 45661 | U12: 18 | V12: 5 | W12: 1 | X12: 0 | Y12: 0 | Z12: 32 | AA12: 70 | AB12: 18 | AC12: 0 | AD12: 0 | AE12: 0 | AF12: 0 | AG12: 0
B13: ACFE | C13: 0 | D13: 291 | E13: 0 | F13: 0 | G13: 291 | H13: 0 | I13: 708 | J13: 0 | K13: 0 | L13: 0 | M13: 1 | N13: 45661 | O13: 0 | P13: 5 | Q13: 45661 | R13: 12 | S13: 50 | T13: 45661 | U13: 18 | V13: 5 | W13: 1 | X13: 0 | Y13: 0 | Z13: 32 | AA13: 70 | AB13: 18 | AC13: 0 | AD13: 0 | AE13: 100 | AF13: 0 | AG13: 0
B14: APER | C14: 1024 | D14: 10656 | E14: 3891 | F14: 0 | G14: 15572 | H14: 53 | I14: 286 | J14: 271 | K14: 0 | L14: 5001 | M14: 0.9521 | N14: 45781 | O14: 4 | P14: 55 | Q14: 45661 | R14: 13 | S14: 20 | T14: 45692 | U14: 18 | V14: 15 | W14: 1 | X14: 0 | Y14: 0 | Z14: 32 | AA14: 70 | AB14: 18 | AC14: 0 | AD14: 79.53 | AE14: 95.78 | AF14: 96.7 | AG14: 0
B15: PERDIDAS ASIGNADAS | C15: 0 | D15: 0 | E15: 0 | F15: 0 | G15: 0 | H15: 0 | I15: 0 | J15: 0 | K15: 0 | L15: 0 | N15: 45661 | O15: 0 | P15: 5 | Q15: 45661 | R15: 6 | S15: 5 | T15: 45661 | U15: 18 | V15: 5 | W15: 1 | X15: 0 | Y15: 0 | Z15: 32 | AA15: 70 | AB15: 18 | AC15: 0 | AD15: 0 | AE15: 0 | AF15: 0 | AG15: 0
B16: PERDIDAS POR COBRAR | C16: 0 | D16: 0 | E16: 0 | F16: 0 | G16: 0 | H16: 0 | I16: 0 | J16: 0 | K16: 0 | L16: 0 | N16: 45661 | O16: 0 | P16: 5 | Q16: 45661 | R16: 6 | S16: 5 | T16: 45661 | U16: 18 | V16: 5 | W16: 1 | X16: 0 | Y16: 0 | Z16: 32 | AA16: 70 | AB16: 18 | AC16: 0 | AD16: 0 | AE16: 0 | AF16: 0 | AG16: 0
B17: ENERGIA TOTAL
A18: 1 | B18: DM24_988121001107_SANBORN HERMANOS SA | C18: 1590 | D18: 5938 | E18: 1638 | F18: 0 | G18: 9166 | H18: 70 | I18: 135 | J18: 109 | K18: 0 | L18: 3807 | M18: 0.9235 | N18: 45781 | O18: 7 | P18: 25 | Q18: 45781 | R18: 15 | S18: 10 | T18: 45751 | U18: 18 | V18: 40 | W18: 1 | X18: 0 | Y18: 0 | Z18: 32 | AA18: 70 | AB18: 18 | AC18: 0 | AD18: 85.86 | AE18: 93.5 | AF18: 93.8 | AG18: 0
A19: 2 | B19: DL70_140110900810_SEARS OPERADORA MEXICO SA D CV | C19: 1147 | D19: 10452 | E19: 1752 | F19: 0 | G19: 13351 | H19: 41 | I19: 396 | J19: 156 | K19: 0 | L19: 4077 | M19: 0.9564 | N19: 45781 | O19: 7 | P19: 55 | Q19: 45720 | R19: 12 | S19: 50 | T19: 45692 | U19: 18 | V19: 25 | W19: 1 | X19: 0 | Y19: 0 | Z19: 32 | AA19: 70 | AB19: 18 | AC19: 0 | AD19: 100 | AE19: 93.64 | AF19: 99.59 | AG19: 0
A20: 3 | B20: DL10_573900901933_SEARS OPERADORA MEXICO SADECV | C20: 792 | D20: 17432 | E20: 3509 | F20: 0 | G20: 21733 | H20: 46 | I20: 492 | J20: 371 | K20: 0 | L20: 10993 | M20: 0.8923 | N20: 45781 | O20: 7 | P20: 55 | Q20: 45781 | R20: 13 | S20: 40 | T20: 45692 | U20: 18 | V20: 25 | W20: 1 | X20: 0 | Y20: 0 | Z20: 32 | AA20: 70 | AB20: 18 | AC20: 0 | AD20: 82.27 | AE20: 88.85 | AF20: 92.47 | AG20: 0
A21: 4 | B21: DM21_147980903088_SEARS OPERADORA MEXICO SA CV | C21: 892 | D21: 15612 | E21: 3881 | F21: 0 | G21: 20385 | H21: 41 | I21: 468 | J21: 435 | K21: 0 | L21: 6951 | M21: 0.9465 | N21: 45781 | O21: 8 | P21: 0 | Q21: 45692 | R21: 13 | S21: 50 | T21: 45692 | U21: 18 | V21: 30 | W21: 1 | X21: 0 | Y21: 0 | Z21: 32 | AA21: 70 | AB21: 18 | AC21: 0 | AD21: 99.73 | AE21: 93.26 | AF21: 97.72 | AG21: 0
A22: 5 | B22: DM21_147071104134_SANBORN HERMANOS SA*TDA RESTAU | C22: 2483 | D22: 12018 | E22: 3226 | F22: 0 | G22: 17728 | H22: 166 | I22: 214 | J22: 209 | K22: 0 | L22: 8665 | M22: 0.8984 | N22: 45781 | O22: 8 | P22: 0 | Q22: 45751 | R22: 12 | S22: 15 | T22: 45751 | U22: 18 | V22: 35 | W22: 1 | X22: 0 | Y22: 0 | Z22: 32 | AA22: 70 | AB22: 18 | AC22: 0 | AD22: 89.7 | AE22: 89.86 | AF22: 89.9 | AG22: 0
A23: 6 | B23: DL10_573700101479_SANBORN HERMANOS S A | C23: 2241 | D23: 8201 | E23: 1895 | F23: 0 | G23: 12337 | H23: 115 | I23: 184 | J23: 137 | K23: 0 | L23: 5028 | M23: 0.926 | N23: 45781 | O23: 8 | P23: 0 | Q23: 45781 | R23: 12 | S23: 30 | T23: 45751 | U23: 18 | V23: 15 | W23: 1 | X23: 0 | Y23: 0 | Z23: 32 | AA23: 70 | AB23: 18 | AC23: 0 | AD23: 91.51 | AE23: 92.88 | AF23: 92.67 | AG23: 0
A24: 7 | B24: DM24_980121000592_SEARS OPERADORA MEX SA DE CV | C24: 1024 | D24: 10656 | E24: 3891 | F24: 0 | G24: 15572 | H24: 53 | I24: 286 | J24: 271 | K24: 0 | L24: 5001 | M24: 0.9521 | N24: 45781 | O24: 4 | P24: 55 | Q24: 45661 | R24: 13 | S24: 20 | T24: 45692 | U24: 18 | V24: 15 | W24: 1 | X24: 0 | Y24: 0 | Z24: 32 | AA24: 70 | AB24: 18 | AC24: 0 | AD24: 79.53 | AE24: 95.78 | AF24: 96.7 | AG24: 0
B25: ENERGIA NORMAL
A26: 1 | B26: DM24_988121001107_SANBORN HERMANOS SA | C26: 0 | D26: 1535 | E26: 1638 | F26: 0 | G26: 3173 | H26: 0 | I26: 55 | J26: 29 | K26: 0 | L26: 0 | M26: 1 | N26: 45661 | O26: 0 | P26: 5 | Q26: 45781 | R26: 15 | S26: 10 | T26: 45751 | U26: 18 | V26: 40 | W26: 1 | X26: 0 | Y26: 0 | Z26: 32 | AA26: 70 | AB26: 18 | AC26: 0 | AD26: 100 | AE26: 100 | AF26: 100 | AG26: 0
A27: 2 | B27: DL70_140110900810_SEARS OPERADORA MEXICO SA D CV | C27: 0 | D27: 10375 | E27: 1752 | F27: 0 | G27: 12127 | H27: 0 | I27: 336 | J27: 96 | K27: 0 | L27: 0 | M27: 1 | N27: 45661 | O27: 0 | P27: 5 | Q27: 45720 | R27: 12 | S27: 50 | T27: 45692 | U27: 18 | V27: 25 | W27: 1 | X27: 0 | Y27: 0 | Z27: 32 | AA27: 70 | AB27: 18 | AC27: 0 | AD27: 100 | AE27: 100 | AF27: 100 | AG27: 0
A28: 3 | B28: DL10_573900901933_SEARS OPERADORA MEXICO SADECV | C28: 0 | D28: 17337 | E28: 3509 | F28: 0 | G28: 20846 | H28: 0 | I28: 412 | J28: 291 | K28: 0 | L28: 0 | M28: 1 | N28: 45661 | O28: 0 | P28: 5 | Q28: 45781 | R28: 13 | S28: 40 | T28: 45692 | U28: 18 | V28: 25 | W28: 1 | X28: 0 | Y28: 0 | Z28: 32 | AA28: 70 | AB28: 18 | AC28: 0 | AD28: 100 | AE28: 100 | AF28: 100 | AG28: 0
A29: 4 | B29: DM21_147980903088_SEARS OPERADORA MEXICO SA CV | C29: 0 | D29: 15557 | E29: 3881 | F29: 0 | G29: 19438 | H29: 0 | I29: 408 | J29: 376 | K29: 0 | L29: 0 | M29: 1 | N29: 45661 | O29: 0 | P29: 5 | Q29: 45692 | R29: 13 | S29: 50 | T29: 45692 | U29: 18 | V29: 30 | W29: 1 | X29: 0 | Y29: 0 | Z29: 32 | AA29: 70 | AB29: 18 | AC29: 0 | AD29: 100 | AE29: 100 | AF29: 100 | AG29: 0
A30: 5 | B30: DM21_147071104134_SANBORN HERMANOS SA*TDA RESTAU | C30: 0 | D30: 12007 | E30: 3226 | F30: 0 | G30: 15233 | H30: 106 | I30: 154 | J30: 149 | K30: 0 | L30: 0 | M30: 1 | N30: 45781 | O30: 8 | P30: 0 | Q30: 45751 | R30: 12 | S30: 15 | T30: 45751 | U30: 18 | V30: 35 | W30: 1 | X30: 0 | Y30: 0 | Z30: 32 | AA30: 70 | AB30: 18 | AC30: 0 | AD30: 100 | AE30: 100 | AF30: 100 | AG30: 0
A31: 6 | B31: DL10_573700101479_SANBORN HERMANOS S A | C31: 496 | D31: 8201 | E31: 1895 | F31: 0 | G31: 10591 | H31: 58 | I31: 127 | J31: 80 | K31: 0 | L31: 0 | M31: 1 | N31: 45781 | O31: 8 | P31: 0 | Q31: 45781 | R31: 12 | S31: 30 | T31: 45751 | U31: 18 | V31: 15 | W31: 1 | X31: 0 | Y31: 0 | Z31: 32 | AA31: 70 | AB31: 18 | AC31: 0 | AD31: 100 | AE31: 100 | AF31: 100 | AG31: 0
A32: 7 | B32: DM24_980121000592_SEARS OPERADORA MEX SA DE CV | C32: 0 | D32: 0 | E32: 0 | F32: 0 | G32: 0 | H32: 53 | I32: 286 | J32: 271 | K32: 0 | L32: 0 | N32: 45781 | O32: 4 | P32: 55 | Q32: 45661 | R32: 13 | S32: 20 | T32: 45692 | U32: 18 | V32: 15 | W32: 1 | X32: 0 | Y32: 0 | Z32: 32 | AA32: 70 | AB32: 18 | AC32: 0 | AD32: 100 | AE32: 100 | AF32: 100 | AG32: 0
B33: ENERGIA PORTEADA
A34: 1 | B34: DM24_988121001107_SANBORN HERMANOS SA | C34: 1590 | D34: 4403 | E34: 0 | F34: 0 | G34: 5992 | H34: 0 | I34: 107 | J34: 0 | K34: 0 | L34: 0 | M34: 1 | N34: 45661 | O34: 0 | P34: 5 | Q34: 45661 | R34: 12 | S34: 55 | T34: 45661 | U34: 18 | V34: 5 | W34: 1 | X34: 0 | Y34: 0 | Z34: 32 | AA34: 70 | AB34: 18 | AC34: 0 | AD34: 0 | AE34: 100 | AF34: 0 | AG34: 0
A35: 2 | B35: DL70_140110900810_SEARS OPERADORA MEXICO SA D CV | C35: 1147 | D35: 77 | E35: 0 | F35: 0 | G35: 1224 | H35: 0 | I35: 155 | J35: 0 | K35: 0 | L35: 0 | M35: 1 | N35: 45661 | O35: 0 | P35: 5 | Q35: 45661 | R35: 12 | S35: 55 | T35: 45661 | U35: 18 | V35: 5 | W35: 1 | X35: 0 | Y35: 0 | Z35: 32 | AA35: 70 | AB35: 18 | AC35: 0 | AD35: 0 | AE35: 100 | AF35: 0 | AG35: 0
A36: 3 | B36: DL10_573900901933_SEARS OPERADORA MEXICO SADECV | C36: 792 | D36: 95 | E36: 0 | F36: 0 | G36: 887 | H36: 0 | I36: 238 | J36: 0 | K36: 0 | L36: 0 | M36: 1 | N36: 45661 | O36: 0 | P36: 5 | Q36: 45661 | R36: 12 | S36: 45 | T36: 45661 | U36: 18 | V36: 5 | W36: 1 | X36: 0 | Y36: 0 | Z36: 32 | AA36: 70 | AB36: 18 | AC36: 0 | AD36: 0 | AE36: 100 | AF36: 0 | AG36: 0
A37: 4 | B37: DM21_147980903088_SEARS OPERADORA MEXICO SA CV | C37: 892 | D37: 56 | E37: 0 | F37: 0 | G37: 948 | H37: 0 | I37: 168 | J37: 0 | K37: 0 | L37: 0 | M37: 1 | N37: 45661 | O37: 0 | P37: 5 | Q37: 45661 | R37: 12 | S37: 50 | T37: 45661 | U37: 18 | V37: 5 | W37: 1 | X37: 0 | Y37: 0 | Z37: 32 | AA37: 70 | AB37: 18 | AC37: 0 | AD37: 0 | AE37: 100 | AF37: 0 | AG37: 0
A38: 5 | B38: DM21_147071104134_SANBORN HERMANOS SA*TDA RESTAU | C38: 2483 | D38: 12 | E38: 0 | F38: 0 | G38: 2494 | H38: 0 | I38: 47 | J38: 0 | K38: 0 | L38: 0 | M38: 1 | N38: 45661 | O38: 0 | P38: 5 | Q38: 45661 | R38: 12 | S38: 50 | T38: 45661 | U38: 18 | V38: 5 | W38: 1 | X38: 0 | Y38: 0 | Z38: 32 | AA38: 70 | AB38: 18 | AC38: 0 | AD38: 0 | AE38: 100 | AF38: 0 | AG38: 0
A39: 6 | B39: DL10_573700101479_SANBORN HERMANOS S A | C39: 1745 | D39: 0 | E39: 0 | F39: 0 | G39: 1745 | H39: 0 | I39: 0 | J39: 0 | K39: 0 | L39: 0 | M39: 1 | N39: 45661 | O39: 0 | P39: 5 | Q39: 45661 | R39: 6 | S39: 5 | T39: 45661 | U39: 18 | V39: 5 | W39: 1 | X39: 0 | Y39: 0 | Z39: 32 | AA39: 70 | AB39: 18 | AC39: 0 | AD39: 0 | AE39: 0 | AF39: 0 | AG39: 0
A40: 7 | B40: DM24_980121000592_SEARS OPERADORA MEX SA DE CV | C40: 1024 | D40: 10656 | E40: 3891 | F40: 0 | G40: 15572 | H40: 0 | I40: 0 | J40: 0 | K40: 0 | L40: 0 | M40: 1 | N40: 45661 | O40: 0 | P40: 5 | Q40: 45661 | R40: 6 | S40: 5 | T40: 45661 | U40: 18 | V40: 5 | W40: 1 | X40: 0 | Y40: 0 | Z40: 32 | AA40: 70 | AB40: 18 | AC40: 0 | AD40: 0 | AE40: 0 | AF40: 0 | AG40: 0
...

Sheet TOTAL
A1: CFE - DIVISION CENTRO ORIENTE
A2: Parámetros de Facturación de Servicios Contratados por Permisionarios y sus Centros de Consumo
A3: Proceso del Permisionario: SBV-CE G Sanborns 2, S.A. de C.V.(Planta Sanborns)
A4: Abril del 2025 Período: 1 | Carga Local : 585 | CapacidadFuente : 1154
C5: KWH | H5: KW | L5: KVARH
C6: Base | D6: Intermedia | E6: Punta | F6: SemiPunta | G6: TOTALES | H6: Base | I6: Intermedia | J6: Punta | K6: SemiPunta
A7: Resultados del Permisionario | B7: TOTAL PORTEADO O TRANSMISION | C7: ='P317202504-SBV-ABR25 compensado'!C63+'P317202504-SBV-ABR25 compensado'!C7 -> 94266 | D7: ='P317202504-SBV-ABR25 compensado'!D63+'P317202504-SBV-ABR25 compensado'!D7 -> 156189 | E7: ='P317202504-SBV-ABR25 compensado'!E63+'P317202504-SBV-ABR25 compensado'!E7 -> 15923 | F7: ='P317202504-SBV-ABR25 compensado'!F63+'P317202504-SBV-ABR25 compensado'!F7 -> 0 | G7: ='P317202504-SBV-ABR25 compensado'!G63+'P317202504-SBV-ABR25 compensado'!G7 -> 266378 | H7: =MAX('P317202504-SBV-ABR25 compensado'!H63,'P317202504-SBV-ABR25 compensado'!H7) -> 756 | I7: =MAX('P317202504-SBV-ABR25 compensado'!I63,'P317202504-SBV-ABR25 compensado'!I7) -> 790 | J7: =MAX('P317202504-SBV-ABR25 compensado'!J63,'P317202504-SBV-ABR25 compensado'!J7) -> 743 | K7: =MAX('P317202504-SBV-ABR25 compensado'!K63,'P317202504-SBV-ABR25 compensado'!K7) -> 0 | L7: ='P317202504-SBV-ABR25 compensado'!L63+'P317202504-SBV-ABR25 compensado'!L7 -> 0
B8: RESPALDO | C8: ='P317202504-SBV-ABR25 compensado'!C64+'P317202504-SBV-ABR25 compensado'!C8 -> 8439 | D8: ='P317202504-SBV-ABR25 compensado'!D64+'P317202504-SBV-ABR25 compensado'!D8 -> 36754 | E8: ='P317202504-SBV-ABR25 compensado'!E64+'P317202504-SBV-ABR25 compensado'!E8 -> 6097 | F8: ='P317202504-SBV-ABR25 compensado'!F64+'P317202504-SBV-ABR25 compensado'!F8 -> 0 | G8: ='P317202504-SBV-ABR25 compensado'!G64+'P317202504-SBV-ABR25 compensado'!G8 -> 51291 | H8: =MAX('P317202504-SBV-ABR25 compensado'!H64,'P317202504-SBV-ABR25 compensado'!H8) -> 270 | I8: =MAX('P317202504-SBV-ABR25 compensado'!I64,'P317202504-SBV-ABR25 compensado'!I8) -> 336 | J8: =MAX('P317202504-SBV-ABR25 compensado'!J64,'P317202504-SBV-ABR25 compensado'!J8) -> 271 | K8: =MAX('P317202504-SBV-ABR25 compensado'!K64,'P317202504-SBV-ABR25 compensado'!K8) -> 0 | L8: ='P317202504-SBV-ABR25 compensado'!L64+'P317202504-SBV-ABR25 compensado'!L8 -> 0
B9: FP DEL RESPALDO (Suministro Normal de la Planta) | C9: ='P317202504-SBV-ABR25 compensado'!C65+'P317202504-SBV-ABR25 compensado'!C9 -> 8439 | D9: ='P317202504-SBV-ABR25 compensado'!D65+'P317202504-SBV-ABR25 compensado'!D9 -> 36754 | E9: ='P317202504-SBV-ABR25 compensado'!E65+'P317202504-SBV-ABR25 compensado'!E9 -> 6097 | F9: ='P317202504-SBV-ABR25 compensado'!F65+'P317202504-SBV-ABR25 compensado'!F9 -> 0 | G9: ='P317202504-SBV-ABR25 compensado'!G65+'P317202504-SBV-ABR25 compensado'!G9 -> 51291 | H9: =MAX('P317202504-SBV-ABR25 compensado'!H65,'P317202504-SBV-ABR25 compensado'!H9) -> 270 | I9: =MAX('P317202504-SBV-ABR25 compensado'!I65,'P317202504-SBV-ABR25 compensado'!I9) -> 336 | J9: =MAX('P317202504-SBV-ABR25 compensado'!J65,'P317202504-SBV-ABR25 compensado'!J9) -> 271 | K9: =MAX('P317202504-SBV-ABR25 compensado'!K65,'P317202504-SBV-ABR25 compensado'!K9) -> 0 | L9: ='P317202504-SBV-ABR25 compensado'!L65+'P317202504-SBV-ABR25 compensado'!L9 -> 17791
B10: BANDA A FAVOR DEL PERMISIONARIO | C10: ='P317202504-SBV-ABR25 compensado'!C66+'P317202504-SBV-ABR25 compensado'!C10 -> 0 | D10: ='P317202504-SBV-ABR25 compensado'!D66+'P317202504-SBV-ABR25 compensado'!D10 -> 0 | E10: ='P317202504-SBV-ABR25 compensado'!E66+'P317202504-SBV-ABR25 compensado'!E10 -> 0 | F10: ='P317202504-SBV-ABR25 compensado'!F66+'P317202504-SBV-ABR25 compensado'!F10 -> 0 | G10: ='P317202504-SBV-ABR25 compensado'!G66+'P317202504-SBV-ABR25 compensado'!G10 -> 0 | H10: =MAX('P317202504-SBV-ABR25 compensado'!H66,'P317202504-SBV-ABR25 compensado'!H10) -> 0 | I10: =MAX('P317202504-SBV-ABR25 compensado'!I66,'P317202504-SBV-ABR25 compensado'!I10) -> 0 | J10: =MAX('P317202504-SBV-ABR25 compensado'!J66,'P317202504-SBV-ABR25 compensado'!J10) -> 0 | K10: =MAX('P317202504-SBV-ABR25 compensado'!K66,'P317202504-SBV-ABR25 compensado'!K10) -> 0 | L10: ='P317202504-SBV-ABR25 compensado'!L66+'P317202504-SBV-ABR25 compensado'!L10 -> 0
B11: BANDA A FAVOR DEL SUMINISTRADOR | C11: ='P317202504-SBV-ABR25 compensado'!C67+'P317202504-SBV-ABR25 compensado'!C11 -> 0 | D11: ='P317202504-SBV-ABR25 compensado'!D67+'P317202504-SBV-ABR25 compensado'!D11 -> 0 | E11: ='P317202504-SBV-ABR25 compensado'!E67+'P317202504-SBV-ABR25 compensado'!E11 -> 0 | F11: ='P317202504-SBV-ABR25 compensado'!F67+'P317202504-SBV-ABR25 compensado'!F11 -> 0 | G11: ='P317202504-SBV-ABR25 compensado'!G67+'P317202504-SBV-ABR25 compensado'!G11 -> 0 | H11: =MAX('P317202504-SBV-ABR25 compensado'!H67,'P317202504-SBV-ABR25 compensado'!H11) -> 0 | I11: =MAX('P317202504-SBV-ABR25 compensado'!I67,'P317202504-SBV-ABR25 compensado'!I11) -> 0 | J11: =MAX('P317202504-SBV-ABR25 compensado'!J67,'P317202504-SBV-ABR25 compensado'!J11) -> 0 | K11: =MAX('P317202504-SBV-ABR25 compensado'!K67,'P317202504-SBV-ABR25 compensado'!K11) -> 0 | L11: ='P317202504-SBV-ABR25 compensado'!L67+'P317202504-SBV-ABR25 compensado'!L11 -> 0
B12: EXCEDENTES | C12: ='P317202504-SBV-ABR25 compensado'!C68+'P317202504-SBV-ABR25 compensado'!C12 -> 0 | D12: ='P317202504-SBV-ABR25 compensado'!D68+'P317202504-SBV-ABR25 compensado'!D12 -> 0 | E12: ='P317202504-SBV-ABR25 compensado'!E68+'P317202504-SBV-ABR25 compensado'!E12 -> 0 | F12: ='P317202504-SBV-ABR25 compensado'!F68+'P317202504-SBV-ABR25 compensado'!F12 -> 0 | G12: ='P317202504-SBV-ABR25 compensado'!G68+'P317202504-SBV-ABR25 compensado'!G12 -> 0 | H12: =MAX('P317202504-SBV-ABR25 compensado'!H68,'P317202504-SBV-ABR25 compensado'!H12) -> 692 | I12: =MAX('P317202504-SBV-ABR25 compensado'!I68,'P317202504-SBV-ABR25 compensado'!I12) -> 679 | J12: =MAX('P317202504-SBV-ABR25 compensado'!J68,'P317202504-SBV-ABR25 compensado'!J12) -> 573 | K12: =MAX('P317202504-SBV-ABR25 compensado'!K68,'P317202504-SBV-ABR25 compensado'!K12) -> 0 | L12: ='P317202504-SBV-ABR25 compensado'!L68+'P317202504-SBV-ABR25 compensado'!L12 -> 0
B13: ACFE | C13: ='P317202504-SBV-ABR25 compensado'!C69+'P317202504-SBV-ABR25 compensado'!C13 -> 96272 | D13: ='P317202504-SBV-ABR25 compensado'!D69+'P317202504-SBV-ABR25 compensado'!D13 -> 155101 | E13: ='P317202504-SBV-ABR25 compensado'!E69+'P317202504-SBV-ABR25 compensado'!E13 -> 15925 | F13: ='P317202504-SBV-ABR25 compensado'!F69+'P317202504-SBV-ABR25 compensado'!F13 -> 0 | G13: ='P317202504-SBV-ABR25 compensado'!G69+'P317202504-SBV-ABR25 compensado'!G13 -> 267298 | H13: =MAX('P317202504-SBV-ABR25 compensado'!H69,'P317202504-SBV-ABR25 compensado'!H13) -> 926 | I13: =MAX('P317202504-SBV-ABR25 compensado'!I69,'P317202504-SBV-ABR25 compensado'!I13) -> 924 | J13: =MAX('P317202504-SBV-ABR25 compensado'!J69,'P317202504-SBV-ABR25 compensado'!J13) -> 907 | K13: =MAX('P317202504-SBV-ABR25 compensado'!K69,'P317202504-SBV-ABR25 compensado'!K13) -> 0 | L13: ='P317202504-SBV-ABR25 compensado'!L69+'P317202504-SBV-ABR25 compensado'!L13 -> 2321
B14: APER | C14: ='P317202504-SBV-ABR25 compensado'!C70+'P317202504-SBV-ABR25 compensado'!C14 -> 8458 | D14: ='P317202504-SBV-ABR25 compensado'!D70+'P317202504-SBV-ABR25 compensado'!D14 -> 36864 | E14: ='P317202504-SBV-ABR25 compensado'!E70+'P317202504-SBV-ABR25 compensado'!E14 -> 6099 | F14: ='P317202504-SBV-ABR25 compensado'!F70+'P317202504-SBV-ABR25 compensado'!F14 -> 0 | G14: ='P317202504-SBV-ABR25 compensado'!G70+'P317202504-SBV-ABR25 compensado'!G14 -> 51421 | H14: =MAX('P317202504-SBV-ABR25 compensado'!H70,'P317202504-SBV-ABR25 compensado'!H14) -> 292 | I14: =MAX('P317202504-SBV-ABR25 compensado'!I70,'P317202504-SBV-ABR25 compensado'!I14) -> 336 | J14: =MAX('P317202504-SBV-ABR25 compensado'!J70,'P317202504-SBV-ABR25 compensado'!J14) -> 271 | K14: =MAX('P317202504-SBV-ABR25 compensado'!K70,'P317202504-SBV-ABR25 compensado'!K14) -> 0 | L14: ='P317202504-SBV-ABR25 compensado'!L70+'P317202504-SBV-ABR25 compensado'!L14 -> 17843
B15: PERDIDAS ASIGNADAS | C15: ='P317202504-SBV-ABR25 compensado'!C71+'P317202504-SBV-ABR25 compensado'!C15 -> 0 | D15: ='P317202504-SBV-ABR25 compensado'!D71+'P317202504-SBV-ABR25 compensado'!D15 -> 0 | E15: ='P317202504-SBV-ABR25 compensado'!E71+'P317202504-SBV-ABR25 compensado'!E15 -> 0 | F15: ='P317202504-SBV-ABR25 compensado'!F71+'P317202504-SBV-ABR25 compensado'!F15 -> 0 | G15: ='P317202504-SBV-ABR25 compensado'!G71+'P317202504-SBV-ABR25 compensado'!G15 -> 0 | H15: =MAX('P317202504-SBV-ABR25 compensado'!H71,'P317202504-SBV-ABR25 compensado'!H15) -> 0 | I15: =MAX('P317202504-SBV-ABR25 compensado'!I71,'P317202504-SBV-ABR25 compensado'!I15) -> 0 | J15: =MAX('P317202504-SBV-ABR25 compensado'!J71,'P317202504-SBV-ABR25 compensado'!J15) -> 0 | K15: =MAX('P317202504-SBV-ABR25 compensado'!K71,'P317202504-SBV-ABR25 compensado'!K15) -> 0 | L15: ='P317202504-SBV-ABR25 compensado'!L71+'P317202504-SBV-ABR25 compensado'!L15 -> 0
B16: PERDIDAS POR COBRAR | C16: ='P317202504-SBV-ABR25 compensado'!C72+'P317202504-SBV-ABR25 compensado'!C16 -> 0 | D16: ='P317202504-SBV-ABR25 compensado'!D72+'P317202504-SBV-ABR25 compensado'!D16 -> 0 | E16: ='P317202504-SBV-ABR25 compensado'!E72+'P317202504-SBV-ABR25 compensado'!E16 -> 0 | F16: ='P317202504-SBV-ABR25 compensado'!F72+'P317202504-SBV-ABR25 compensado'!F16 -> 0 | G16: ='P317202504-SBV-ABR25 compensado'!G72+'P317202504-SBV-ABR25 compensado'!G16 -> 0 | H16: =MAX('P317202504-SBV-ABR25 compensado'!H72,'P317202504-SBV-ABR25 compensado'!H16) -> 0 | I16: =MAX('P317202504-SBV-ABR25 compensado'!I72,'P317202504-SBV-ABR25 compensado'!I16) -> 0 | J16: =MAX('P317202504-SBV-ABR25 compensado'!J72,'P317202504-SBV-ABR25 compensado'!J16) -> 0 | K16: =MAX('P317202504-SBV-ABR25 compensado'!K72,'P317202504-SBV-ABR25 compensado'!K16) -> 0 | L16: ='P317202504-SBV-ABR25 compensado'!L72+'P317202504-SBV-ABR25 compensado'!L16 -> 0
B17: ENERGIA TOTAL
A18: 1 | B18: DM24_988121001107_SANBORN HERMANOS SA | C18: ='P317202504-SBV-ABR25 compensado'!C74+'P317202504-SBV-ABR25 compensado'!C18 -> 13202 | D18: ='P317202504-SBV-ABR25 compensado'!D74+'P317202504-SBV-ABR25 compensado'!D18 -> 35511 | E18: ='P317202504-SBV-ABR25 compensado'!E74+'P317202504-SBV-ABR25 compensado'!E18 -> 4567 | F18: ='P317202504-SBV-ABR25 compensado'!F74+'P317202504-SBV-ABR25 compensado'!F18 -> 0 | G18: ='P317202504-SBV-ABR25 compensado'!G74+'P317202504-SBV-ABR25 compensado'!G18 -> 53280 | H18: =MAX('P317202504-SBV-ABR25 compensado'!H74,'P317202504-SBV-ABR25 compensado'!H18) -> 134 | I18: =MAX('P317202504-SBV-ABR25 compensado'!I74,'P317202504-SBV-ABR25 compensado'!I18) -> 138 | J18: =MAX('P317202504-SBV-ABR25 compensado'!J74,'P317202504-SBV-ABR25 compensado'!J18) -> 118 | K18: =MAX('P317202504-SBV-ABR25 compensado'!K74,'P317202504-SBV-ABR25 compensado'!K18) -> 0 | L18: ='P317202504-SBV-ABR25 compensado'!L74+'P317202504-SBV-ABR25 compensado'!L18 -> 21438
A19: 2 | B19: DL70_140110900810_SEARS OPERADORA MEXICO SA D CV | C19: ='P317202504-SBV-ABR25 compensado'!C75+'P317202504-SBV-ABR25 compensado'!C19 -> 14394 | D19: ='P317202504-SBV-ABR25 compensado'!D75+'P317202504-SBV-ABR25 compensado'!D19 -> 52762 | E19: ='P317202504-SBV-ABR25 compensado'!E75+'P317202504-SBV-ABR25 compensado'!E19 -> 4158 | F19: ='P317202504-SBV-ABR25 compensado'!F75+'P317202504-SBV-ABR25 compensado'!F19 -> 0 | G19: ='P317202504-SBV-ABR25 compensado'!G75+'P317202504-SBV-ABR25 compensado'!G19 -> 71314 | H19: =MAX('P317202504-SBV-ABR25 compensado'!H75,'P317202504-SBV-ABR25 compensado'!H19) -> 350 | I19: =MAX('P317202504-SBV-ABR25 compensado'!I75,'P317202504-SBV-ABR25 compensado'!I19) -> 396 | J19: =MAX('P317202504-SBV-ABR25 compensado'!J75,'P317202504-SBV-ABR25 compensado'!J19) -> 156 | K19: =MAX('P317202504-SBV-ABR25 compensado'!K75,'P317202504-SBV-ABR25 compensado'!K19) -> 0 | L19: ='P317202504-SBV-ABR25 compensado'!L75+'P317202504-SBV-ABR25 compensado'!L19 -> 19019
A20: 3 | B20: DL10_573900901933_SEARS OPERADORA MEXICO SADECV | C20: ='P317202504-SBV-ABR25 compensado'!C76+'P317202504-SBV-ABR25 compensado'!C20 -> 19504 | D20: ='P317202504-SBV-ABR25 compensado'!D76+'P317202504-SBV-ABR25 compensado'!D20 -> 106052 | E20: ='P317202504-SBV-ABR25 compensado'!E76+'P317202504-SBV-ABR25 compensado'!E20 -> 7559 | F20: ='P317202504-SBV-ABR25 compensado'!F76+'P317202504-SBV-ABR25 compensado'!F20 -> 0 | G20: ='P317202504-SBV-ABR25 compensado'!G76+'P317202504-SBV-ABR25 compensado'!G20 -> 133114 | H20: =MAX('P317202504-SBV-ABR25 compensado'!H76,'P317202504-SBV-ABR25 compensado'!H20) -> 483 | I20: =MAX('P317202504-SBV-ABR25 compensado'!I76,'P317202504-SBV-ABR25 compensado'!I20) -> 495 | J20: =MAX('P317202504-SBV-ABR25 compensado'!J76,'P317202504-SBV-ABR25 compensado'!J20) -> 371 | K20: =MAX('P317202504-SBV-ABR25 compensado'!K76,'P317202504-SBV-ABR25 compensado'!K20) -> 0 | L20: ='P317202504-SBV-ABR25 compensado'!L76+'P317202504-SBV-ABR25 compensado'!L20 -> 68346
A21: 4 | B21: DM21_147980903088_SEARS OPERADORA MEXICO SA CV | C21: ='P317202504-SBV-ABR25 compensado'!C77+'P317202504-SBV-ABR25 compensado'!C21 -> 18328 | D21: ='P317202504-SBV-ABR25 compensado'!D77+'P317202504-SBV-ABR25 compensado'!D21 -> 91312 | E21: ='P317202504-SBV-ABR25 compensado'!E77+'P317202504-SBV-ABR25 compensado'!E21 -> 8871 | F21: ='P317202504-SBV-ABR25 compensado'!F77+'P317202504-SBV-ABR25 compensado'!F21 -> 0 | G21: ='P317202504-SBV-ABR25 compensado'!G77+'P317202504-SBV-ABR25 compensado'!G21 -> 118511 | H21: =MAX('P317202504-SBV-ABR25 compensado'!H77,'P317202504-SBV-ABR25 compensado'!H21) -> 506 | I21: =MAX('P317202504-SBV-ABR25 compensado'!I77,'P317202504-SBV-ABR25 compensado'!I21) -> 506 | J21: =MAX('P317202504-SBV-ABR25 compensado'!J77,'P317202504-SBV-ABR25 compensado'!J21) -> 435 | K21: =MAX('P317202504-SBV-ABR25 compensado'!K77,'P317202504-SBV-ABR25 compensado'!K21) -> 0 | L21: ='P317202504-SBV-ABR25 compensado'!L77+'P317202504-SBV-ABR25 compensado'!L21 -> 37877
A22: 5 | B22: DM21_147071104134_SANBORN HERMANOS SA*TDA RESTAU | C22: ='P317202504-SBV-ABR25 compensado'!C78+'P317202504-SBV-ABR25 compensado'!C22 -> 22661 | D22: ='P317202504-SBV-ABR25 compensado'!D78+'P317202504-SBV-ABR25 compensado'!D22 -> 70259 | E22: ='P317202504-SBV-ABR25 compensado'!E78+'P317202504-SBV-ABR25 compensado'!E22 -> 8758 | F22: ='P317202504-SBV-ABR25 compensado'!F78+'P317202504-SBV-ABR25 compensado'!F22 -> 0 | G22: ='P317202504-SBV-ABR25 compensado'!G78+'P317202504-SBV-ABR25 compensado'!G22 -> 101679 | H22: =MAX('P317202504-SBV-ABR25 compensado'!H78,'P317202504-SBV-ABR25 compensado'!H22) -> 231 | I22: =MAX('P317202504-SBV-ABR25 compensado'!I78,'P317202504-SBV-ABR25 compensado'!I22) -> 240 | J22: =MAX('P317202504-SBV-ABR25 compensado'!J78,'P317202504-SBV-ABR25 compensado'!J22) -> 220 | K22: =MAX('P317202504-SBV-ABR25 compensado'!K78,'P317202504-SBV-ABR25 compensado'!K22) -> 0 | L22: ='P317202504-SBV-ABR25 compensado'!L78+'P317202504-SBV-ABR25 compensado'!L22 -> 48293
A23: 6 | B23: DL10_573700101479_SANBORN HERMANOS S A | C23: ='P317202504-SBV-ABR25 compensado'!C79+'P317202504-SBV-ABR25 compensado'!C23 -> 17539 | D23: ='P317202504-SBV-ABR25 compensado'!D79+'P317202504-SBV-ABR25 compensado'!D23 -> 47652 | E23: ='P317202504-SBV-ABR25 compensado'!E79+'P317202504-SBV-ABR25 compensado'!E23 -> 5036 | F23: ='P317202504-SBV-ABR25 compensado'!F79+'P317202504-SBV-ABR25 compensado'!F23 -> 0 | G23: ='P317202504-SBV-ABR25 compensado'!G79+'P317202504-SBV-ABR25 compensado'!G23 -> 70227 | H23: =MAX('P317202504-SBV-ABR25 compensado'!H79,'P317202504-SBV-ABR25 compensado'!H23) -> 178 | I23: =MAX('P317202504-SBV-ABR25 compensado'!I79,'P317202504-SBV-ABR25 compensado'!I23) -> 184 | J23: =MAX('P317202504-SBV-ABR25 compensado'!J79,'P317202504-SBV-ABR25 compensado'!J23) -> 137 | K23: =MAX('P317202504-SBV-ABR25 compensado'!K79,'P317202504-SBV-ABR25 compensado'!K23) -> 0 | L23: ='P317202504-SBV-ABR25 compensado'!L79+'P317202504-SBV-ABR25 compensado'!L23 -> 28697
A24: 7 | B24: DM24_980121000592_SEARS OPERADORA MEX SA DE CV | C24: ='P317202504-SBV-ABR25 compensado'!C80+'P317202504-SBV-ABR25 compensado'!C24 -> 8439 | D24: ='P317202504-SBV-ABR25 compensado'!D80+'P317202504-SBV-ABR25 compensado'!D24 -> 36754 | E24: ='P317202504-SBV-ABR25 compensado'!E80+'P317202504-SBV-ABR25 compensado'!E24 -> 6097 | F24: ='P317202504-SBV-ABR25 compensado'!F80+'P317202504-SBV-ABR25 compensado'!F24 -> 0 | G24: ='P317202504-SBV-ABR25 compensado'!G80+'P317202504-SBV-ABR25 compensado'!G24 -> 51291 | H24: =MAX('P317202504-SBV-ABR25 compensado'!H80,'P317202504-SBV-ABR25 compensado'!H24) -> 270 | I24: =MAX('P317202504-SBV-ABR25 compensado'!I80,'P317202504-SBV-ABR25 compensado'!I24) -> 336 | J24: =MAX('P317202504-SBV-ABR25 compensado'!J80,'P317202504-SBV-ABR25 compensado'!J24) -> 271 | K24: =MAX('P317202504-SBV-ABR25 compensado'!K80,'P317202504-SBV-ABR25 compensado'!K24) -> 0 | L24: ='P317202504-SBV-ABR25 compensado'!L80+'P317202504-SBV-ABR25 compensado'!L24 -> 17842
B25: ENERGIA NORMAL
A26: 1 | B26: DM24_988121001107_SANBORN HERMANOS SA | C26: ='P317202504-SBV-ABR25 compensado'!C82+'P317202504-SBV-ABR25 compensado'!C26 -> 71 | D26: ='P317202504-SBV-ABR25 compensado'!D82+'P317202504-SBV-ABR25 compensado'!D26 -> 13239 | E26: ='P317202504-SBV-ABR25 compensado'!E82+'P317202504-SBV-ABR25 compensado'!E26 -> 2715 | F26: ='P317202504-SBV-ABR25 compensado'!F82+'P317202504-SBV-ABR25 compensado'!F26 -> 0 | G26: ='P317202504-SBV-ABR25 compensado'!G82+'P317202504-SBV-ABR25 compensado'!G26 -> 16025 | H26: =MAX('P317202504-SBV-ABR25 compensado'!H82,'P317202504-SBV-ABR25 compensado'!H26) -> 55 | I26: =MAX('P317202504-SBV-ABR25 compensado'!I82,'P317202504-SBV-ABR25 compensado'!I26) -> 58 | J26: =MAX('P317202504-SBV-ABR25 compensado'!J82,'P317202504-SBV-ABR25 compensado'!J26) -> 39 | K26: =MAX('P317202504-SBV-ABR25 compensado'!K82,'P317202504-SBV-ABR25 compensado'!K26) -> 0 | L26: ='P317202504-SBV-ABR25 compensado'!L82+'P317202504-SBV-ABR25 compensado'!L26 -> 0
A27: 2 | B27: DL70_140110900810_SEARS OPERADORA MEXICO SA D CV | C27: ='P317202504-SBV-ABR25 compensado'!C83+'P317202504-SBV-ABR25 compensado'!C27 -> 1695 | D27: ='P317202504-SBV-ABR25 compensado'!D83+'P317202504-SBV-ABR25 compensado'!D27 -> 30830 | E27: ='P317202504-SBV-ABR25 compensado'!E83+'P317202504-SBV-ABR25 compensado'!E27 -> 2653 | F27: ='P317202504-SBV-ABR25 compensado'!F83+'P317202504-SBV-ABR25 compensado'!F27 -> 0 | G27: ='P317202504-SBV-ABR25 compensado'!G83+'P317202504-SBV-ABR25 compensado'!G27 -> 35179 | H27: =MAX('P317202504-SBV-ABR25 compensado'!H83,'P317202504-SBV-ABR25 compensado'!H27) -> 291 | I27: =MAX('P317202504-SBV-ABR25 compensado'!I83,'P317202504-SBV-ABR25 compensado'!I27) -> 336 | J27: =MAX('P317202504-SBV-ABR25 compensado'!J83,'P317202504-SBV-ABR25 compensado'!J27) -> 96 | K27: =MAX('P317202504-SBV-ABR25 compensado'!K83,'P317202504-SBV-ABR25 compensado'!K27) -> 0 | L27: ='P317202504-SBV-ABR25 compensado'!L83+'P317202504-SBV-ABR25 compensado'!L27 -> 0
A28: 3 | B28: DL10_573900901933_SEARS OPERADORA MEXICO SADECV | C28: ='P317202504-SBV-ABR25 compensado'!C84+'P317202504-SBV-ABR25 compensado'!C28 -> 5803 | D28: ='P317202504-SBV-ABR25 compensado'!D84+'P317202504-SBV-ABR25 compensado'!D28 -> 71904 | E28: ='P317202504-SBV-ABR25 compensado'!E84+'P317202504-SBV-ABR25 compensado'!E28 -> 5192 | F28: ='P317202504-SBV-ABR25 compensado'!F84+'P317202504-SBV-ABR25 compensado'!F28 -> 0 | G28: ='P317202504-SBV-ABR25 compensado'!G84+'P317202504-SBV-ABR25 compensado'!G28 -> 82899 | H28: =MAX('P317202504-SBV-ABR25 compensado'!H84,'P317202504-SBV-ABR25 compensado'!H28) -> 403 | I28: =MAX('P317202504-SBV-ABR25 compensado'!I84,'P317202504-SBV-ABR25 compensado'!I28) -> 416 | J28: =MAX('P317202504-SBV-ABR25 compensado'!J84,'P317202504-SBV-ABR25 compensado'!J28) -> 291 | K28: =MAX('P317202504-SBV-ABR25 compensado'!K84,'P317202504-SBV-ABR25 compensado'!K28) -> 0 | L28: ='P317202504-SBV-ABR25 compensado'!L84+'P317202504-SBV-ABR25 compensado'!L28 -> 0
A29: 4 | B29: DM21_147980903088_SEARS OPERADORA MEXICO SA CV | C29: ='P317202504-SBV-ABR25 compensado'!C85+'P317202504-SBV-ABR25 compensado'!C29 -> 6493 | D29: ='P317202504-SBV-ABR25 compensado'!D85+'P317202504-SBV-ABR25 compensado'!D29 -> 69810 | E29: ='P317202504-SBV-ABR25 compensado'!E85+'P317202504-SBV-ABR25 compensado'!E29 -> 6387 | F29: ='P317202504-SBV-ABR25 compensado'!F85+'P317202504-SBV-ABR25 compensado'!F29 -> 0 | G29: ='P317202504-SBV-ABR25 compensado'!G85+'P317202504-SBV-ABR25 compensado'!G29 -> 82691 | H29: =MAX('P317202504-SBV-ABR25 compensado'!H85,'P317202504-SBV-ABR25 compensado'!H29) -> 447 | I29: =MAX('P317202504-SBV-ABR25 compensado'!I85,'P317202504-SBV-ABR25 compensado'!I29) -> 446 | J29: =MAX('P317202504-SBV-ABR25 compensado'!J85,'P317202504-SBV-ABR25 compensado'!J29) -> 376 | K29: =MAX('P317202504-SBV-ABR25 compensado'!K85,'P317202504-SBV-ABR25 compensado'!K29) -> 0 | L29: ='P317202504-SBV-ABR25 compensado'!L85+'P317202504-SBV-ABR25 compensado'!L29 -> 0
A30: 5 | B30: DM21_147071104134_SANBORN HERMANOS SA*TDA RESTAU | C30: ='P317202504-SBV-ABR25 compensado'!C86+'P317202504-SBV-ABR25 compensado'!C30 -> 891 | D30: ='P317202504-SBV-ABR25 compensado'!D86+'P317202504-SBV-ABR25 compensado'!D30 -> 56010 | E30: ='P317202504-SBV-ABR25 compensado'!E86+'P317202504-SBV-ABR25 compensado'!E30 -> 5930 | F30: ='P317202504-SBV-ABR25 compensado'!F86+'P317202504-SBV-ABR25 compensado'!F30 -> 0 | G30: ='P317202504-SBV-ABR25 compensado'!G86+'P317202504-SBV-ABR25 compensado'!G30 -> 62831 | H30: =MAX('P317202504-SBV-ABR25 compensado'!H86,'P317202504-SBV-ABR25 compensado'!H30) -> 171 | I30: =MAX('P317202504-SBV-ABR25 compensado'!I86,'P317202504-SBV-ABR25 compensado'!I30) -> 180 | J30: =MAX('P317202504-SBV-ABR25 compensado'!J86,'P317202504-SBV-ABR25 compensado'!J30) -> 161 | K30: =MAX('P317202504-SBV-ABR25 compensado'!K86,'P317202504-SBV-ABR25 compensado'!K30) -> 0 | L30: ='P317202504-SBV-ABR25 compensado'!L86+'P317202504-SBV-ABR25 compensado'!L30 -> 0
A31: 6 | B31: DL10_573700101479_SANBORN HERMANOS S A | C31: ='P317202504-SBV-ABR25 compensado'!C87+'P317202504-SBV-ABR25 compensado'!C31 -> 4847 | D31: ='P317202504-SBV-ABR25 compensado'!D87+'P317202504-SBV-ABR25 compensado'!D31 -> 42321 | E31: ='P317202504-SBV-ABR25 compensado'!E87+'P317202504-SBV-ABR25 compensado'!E31 -> 4104 | F31: ='P317202504-SBV-ABR25 compensado'!F87+'P317202504-SBV-ABR25 compensado'!F31 -> 0 | G31: ='P317202504-SBV-ABR25 compensado'!G87+'P317202504-SBV-ABR25 compensado'!G31 -> 51272 | H31: =MAX('P317202504-SBV-ABR25 compensado'!H87,'P317202504-SBV-ABR25 compensado'!H31) -> 121 | I31: =MAX('P317202504-SBV-ABR25 compensado'!I87,'P317202504-SBV-ABR25 compensado'!I31) -> 127 | J31: =MAX('P317202504-SBV-ABR25 compensado'!J87,'P317202504-SBV-ABR25 compensado'!J31) -> 80 | K31: =MAX('P317202504-SBV-ABR25 compensado'!K87,'P317202504-SBV-ABR25 compensado'!K31) -> 0 | L31: ='P317202504-SBV-ABR25 compensado'!L87+'P317202504-SBV-ABR25 compensado'!L31 -> 0
A32: 7 | B32: DM24_980121000592_SEARS OPERADORA MEX SA DE CV | C32: ='P317202504-SBV-ABR25 compensado'!C88+'P317202504-SBV-ABR25 compensado'!C32 -> 0 | D32: ='P317202504-SBV-ABR25 compensado'!D88+'P317202504-SBV-ABR25 compensado'!D32 -> 0 | E32: ='P317202504-SBV-ABR25 compensado'!E88+'P317202504-SBV-ABR25 compensado'!E32 -> 2140 | F32: ='P317202504-SBV-ABR25 compensado'!F88+'P317202504-SBV-ABR25 compensado'!F32 -> 0 | G32: ='P317202504-SBV-ABR25 compensado'!G88+'P317202504-SBV-ABR25 compensado'!G32 -> 2140 | H32: =MAX('P317202504-SBV-ABR25 compensado'!H88,'P317202504-SBV-ABR25 compensado'!H32) -> 270 | I32: =MAX('P317202504-SBV-ABR25 compensado'!I88,'P317202504-SBV-ABR25 compensado'!I32) -> 336 | J32: =MAX('P317202504-SBV-ABR25 compensado'!J88,'P317202504-SBV-ABR25 compensado'!J32) -> 271 | K32: =MAX('P317202504-SBV-ABR25 compensado'!K88,'P317202504-SBV-ABR25 compensado'!K32) -> 0 | L32: ='P317202504-SBV-ABR25 compensado'!L88+'P317202504-SBV-ABR25 compensado'!L32 -> 0
B33: ENERGIA PORTEADA
A34: 1 | B34: DM24_988121001107_SANBORN HERMANOS SA | C34: ='P317202504-SBV-ABR25 compensado'!C90+'P317202504-SBV-ABR25 compensado'!C34 -> 13131 | D34: ='P317202504-SBV-ABR25 compensado'!D90+'P317202504-SBV-ABR25 compensado'!D34 -> 22273 | E34: ='P317202504-SBV-ABR25 compensado'!E90+'P317202504-SBV-ABR25 compensado'!E34 -> 1851 | F34: ='P317202504-SBV-ABR25 compensado'!F90+'P317202504-SBV-ABR25 compensado'!F34 -> 0 | G34: ='P317202504-SBV-ABR25 compensado'!G90+'P317202504-SBV-ABR25 compensado'!G34 -> 37254 | H34: =MAX('P317202504-SBV-ABR25 compensado'!H90,'P317202504-SBV-ABR25 compensado'!H34) -> 107 | I34: =MAX('P317202504-SBV-ABR25 compensado'!I90,'P317202504-SBV-ABR25 compensado'!I34) -> 107 | J34: =MAX('P317202504-SBV-ABR25 compensado'!J90,'P317202504-SBV-ABR25 compensado'!J34) -> 107 | K34: =MAX('P317202504-SBV-ABR25 compensado'!K90,'P317202504-SBV-ABR25 compensado'!K34) -> 0 | L34: ='P317202504-SBV-ABR25 compensado'!L90+'P317202504-SBV-ABR25 compensado'!L34 -> 0
A35: 2 | B35: DL70_140110900810_SEARS OPERADORA MEXICO SA D CV | C35: ='P317202504-SBV-ABR25 compensado'!C91+'P317202504-SBV-ABR25 compensado'!C35 -> 12698 | D35: ='P317202504-SBV-ABR25 compensado'!D91+'P317202504-SBV-ABR25 compensado'!D35 -> 21932 | E35: ='P317202504-SBV-ABR25 compensado'!E91+'P317202504-SBV-ABR25 compensado'!E35 -> 1505 | F35: ='P317202504-SBV-ABR25 compensado'!F91+'P317202504-SBV-ABR25 compensado'!F35 -> 0 | G35: ='P317202504-SBV-ABR25 compensado'!G91+'P317202504-SBV-ABR25 compensado'!G35 -> 36135 | H35: =MAX('P317202504-SBV-ABR25 compensado'!H91,'P317202504-SBV-ABR25 compensado'!H35) -> 178 | I35: =MAX('P317202504-SBV-ABR25 compensado'!I91,'P317202504-SBV-ABR25 compensado'!I35) -> 178 | J35: =MAX('P317202504-SBV-ABR25 compensado'!J91,'P317202504-SBV-ABR25 compensado'!J35) -> 108 | K35: =MAX('P317202504-SBV-ABR25 compensado'!K91,'P317202504-SBV-ABR25 compensado'!K35) -> 0 | L35: ='P317202504-SBV-ABR25 compensado'!L91+'P317202504-SBV-ABR25 compensado'!L35 -> 0
A36: 3 | B36: DL10_573900901933_SEARS OPERADORA MEXICO SADECV | C36: ='P317202504-SBV-ABR25 compensado'!C92+'P317202504-SBV-ABR25 compensado'!C36 -> 13701 | D36: ='P317202504-SBV-ABR25 compensado'!D92+'P317202504-SBV-ABR25 compensado'!D36 -> 34148 | E36: ='P317202504-SBV-ABR25 compensado'!E92+'P317202504-SBV-ABR25 compensado'!E36 -> 2367 | F36: ='P317202504-SBV-ABR25 compensado'!F92+'P317202504-SBV-ABR25 compensado'!F36 -> 0 | G36: ='P317202504-SBV-ABR25 compensado'!G92+'P317202504-SBV-ABR25 compensado'!G36 -> 50215 | H36: =MAX('P317202504-SBV-ABR25 compensado'!H92,'P317202504-SBV-ABR25 compensado'!H36) -> 238 | I36: =MAX('P317202504-SBV-ABR25 compensado'!I92,'P317202504-SBV-ABR25 compensado'!I36) -> 238 | J36: =MAX('P317202504-SBV-ABR25 compensado'!J92,'P317202504-SBV-ABR25 compensado'!J36) -> 238 | K36: =MAX('P317202504-SBV-ABR25 compensado'!K92,'P317202504-SBV-ABR25 compensado'!K36) -> 0 | L36: ='P317202504-SBV-ABR25 compensado'!L92+'P317202504-SBV-ABR25 compensado'!L36 -> 0
A37: 4 | B37: DM21_147980903088_SEARS OPERADORA MEXICO SA CV | C37: ='P317202504-SBV-ABR25 compensado'!C93+'P317202504-SBV-ABR25 compensado'!C37 -> 11835 | D37: ='P317202504-SBV-ABR25 compensado'!D93+'P317202504-SBV-ABR25 compensado'!D37 -> 21503 | E37: ='P317202504-SBV-ABR25 compensado'!E93+'P317202504-SBV-ABR25 compensado'!E37 -> 2484 | F37: ='P317202504-SBV-ABR25 compensado'!F93+'P317202504-SBV-ABR25 compensado'!F37 -> 0 | G37: ='P317202504-SBV-ABR25 compensado'!G93+'P317202504-SBV-ABR25 compensado'!G37 -> 35822 | H37: =MAX('P317202504-SBV-ABR25 compensado'!H93,'P317202504-SBV-ABR25 compensado'!H37) -> 168 | I37: =MAX('P317202504-SBV-ABR25 compensado'!I93,'P317202504-SBV-ABR25 compensado'!I37) -> 168 | J37: =MAX('P317202504-SBV-ABR25 compensado'!J93,'P317202504-SBV-ABR25 compensado'!J37) -> 168 | K37: =MAX('P317202504-SBV-ABR25 compensado'!K93,'P317202504-SBV-ABR25 compensado'!K37) -> 0 | L37: ='P317202504-SBV-ABR25 compensado'!L93+'P317202504-SBV-ABR25 compensado'!L37 -> 0
A38: 5 | B38: DM21_147071104134_SANBORN HERMANOS SA*TDA RESTAU | C38: ='P317202504-SBV-ABR25 compensado'!C94+'P317202504-SBV-ABR25 compensado'!C38 -> 21770 | D38: ='P317202504-SBV-ABR25 compensado'!D94+'P317202504-SBV-ABR25 compensado'!D38 -> 14250 | E38: ='P317202504-SBV-ABR25 compensado'!E94+'P317202504-SBV-ABR25 compensado'!E38 -> 2828 | F38: ='P317202504-SBV-ABR25 compensado'!F94+'P317202504-SBV-ABR25 compensado'!F38 -> 0 | G38: ='P317202504-SBV-ABR25 compensado'!G94+'P317202504-SBV-ABR25 compensado'!G38 -> 38847 | H38: =MAX('P317202504-SBV-ABR25 compensado'!H94,'P317202504-SBV-ABR25 compensado'!H38) -> 169 | I38: =MAX('P317202504-SBV-ABR25 compensado'!I94,'P317202504-SBV-ABR25 compensado'!I38) -> 169 | J38: =MAX('P317202504-SBV-ABR25 compensado'!J94,'P317202504-SBV-ABR25 compensado'!J38) -> 169 | K38: =MAX('P317202504-SBV-ABR25 compensado'!K94,'P317202504-SBV-ABR25 compensado'!K38) -> 0 | L38: ='P317202504-SBV-ABR25 compensado'!L94+'P317202504-SBV-ABR25 compensado'!L38 -> 0
A39: 6 | B39: DL10_573700101479_SANBORN HERMANOS S A | C39: ='P317202504-SBV-ABR25 compensado'!C95+'P317202504-SBV-ABR25 compensado'!C39 -> 12692 | D39: ='P317202504-SBV-ABR25 compensado'!D95+'P317202504-SBV-ABR25 compensado'!D39 -> 5331 | E39: ='P317202504-SBV-ABR25 compensado'!E95+'P317202504-SBV-ABR25 compensado'!E39 -> 932 | F39: ='P317202504-SBV-ABR25 compensado'!F95+'P317202504-SBV-ABR25 compensado'!F39 -> 0 | G39: ='P317202504-SBV-ABR25 compensado'!G95+'P317202504-SBV-ABR25 compensado'!G39 -> 18955 | H39: =MAX('P317202504-SBV-ABR25 compensado'!H95,'P317202504-SBV-ABR25 compensado'!H39) -> 57 | I39: =MAX('P317202504-SBV-ABR25 compensado'!I95,'P317202504-SBV-ABR25 compensado'!I39) -> 57 | J39: =MAX('P317202504-SBV-ABR25 compensado'!J95,'P317202504-SBV-ABR25 compensado'!J39) -> 57 | K39: =MAX('P317202504-SBV-ABR25 compensado'!K95,'P317202504-SBV-ABR25 compensado'!K39) -> 0 | L39: ='P317202504-SBV-ABR25 compensado'!L95+'P317202504-SBV-ABR25 compensado'!L39 -> 0
A40: 7 | B40: DM24_980121000592_SEARS OPERADORA MEX SA DE CV | C40: ='P317202504-SBV-ABR25 compensado'!C96+'P317202504-SBV-ABR25 compensado'!C40 -> 8439 | D40: ='P317202504-SBV-ABR25 compensado'!D96+'P317202504-SBV-ABR25 compensado'!D40 -> 36754 | E40: ='P317202504-SBV-ABR25 compensado'!E96+'P317202504-SBV-ABR25 compensado'!E40 -> 3957 | F40: ='P317202504-SBV-ABR25 compensado'!F96+'P317202504-SBV-ABR25 compensado'!F40 -> 0 | G40: ='P317202504-SBV-ABR25 compensado'!G96+'P317202504-SBV-ABR25 compensado'!G40 -> 49151 | H40: =MAX('P317202504-SBV-ABR25 compensado'!H96,'P317202504-SBV-ABR25 compensado'!H40) -> 0 | I40: =MAX('P317202504-SBV-ABR25 compensado'!I96,'P317202504-SBV-ABR25 compensado'!I40) -> 0 | J40: =MAX('P317202504-SBV-ABR25 compensado'!J96,'P317202504-SBV-ABR25 compensado'!J40) -> 0 | K40: =MAX('P317202504-SBV-ABR25 compensado'!K96,'P317202504-SBV-ABR25 compensado'!K40) -> 0 | L40: ='P317202504-SBV-ABR25 compensado'!L96+'P317202504-SBV-ABR25 compensado'!L40 -> 0
...
